Workbook

Sheet Clients
A1: Nom | B1: Email | C1: Phone | D1: Language | E1: Date Formulaire | F1: Date Event | G1: Heure Début | H1: Heure Fin | I1: Lieu Event | J1: Type Event | K1: Invités | L1: Pack | M1: Pack (€) | N1: Transport (€) | O1: Supplément | P1: Supplément (h) | Q1: Supplément (€) | R1: Date acompte payé | S1: Acompte | T1: Total | U1: Solde Restant | V1: Etudiant | W1: Heures Etudiant | X1: Etudiant €/Event | Y1: KM (Aller) | Z1: KM (Total) | AA1: Coût Essence | AB1: Commercial | AC1: Comm Commercial | AD1: Marge Brut (Event) | AE1: Lien Invoice | AF1: Lien Galerie | AG1: Lien ZIP | AH1: Event ID | AI1: Sync Status | AJ1: Review Status | AK1: Annual Offer Status | AL1: Acompte Facture | AM1: Solde Facture
A2: Hanan et Geoffrey - Zara | C2: 0485 70 88 23 | D2: FR | F2: 45668 | J2: B2B | L2: Premium | M2: 700 | T2: =M2 -> 700 | U2: 700 | V2: Abdel | W2: 4.5 | X2: 70 | Y2: 65 | Z2: 260 | AA2: 39 | AC2: =IF(OR(L2="", AB2=""), 0, IF(L2="Découverte", KPI!$F$2, IF(L2="Essentiel", KPI!$F$3, IF(L2="Premium", KPI!$F$4, 0) ) ) ) -> 0 | AD2: {=IF(F2="", "", (T2 / 1.21) - IF(L2="Découverte", KPI!$C$2, IF(L2="Essentiel", KPI!$C$3, IF(L2="Premium", KPI!$C$4, 0) ) ) - N(X2) - N(AA2) - N(AC2) - IFERROR(INDEX(Stats!$G:$G, MATCH(DATE(YEAR(R2), MONTH(R2), 1), Stats!$A:$A, 0)), 35) )} -> 342.0124 | AH2: 8lv5q8g0s9fm99631th446r44c@google.com | AI2: OK 2026-01-02 09:35
A3: Angélique Crucilla - Commune Fleurus | C3: 0483/12.26.35 | D3: FR | F3: 45672 | I3: Chemin de Mons 61, Fleurus | J3: B2B | L3: Essentiel | M3: 645 | T3: =M3 -> 645 | U3: 645 | V3: Abdel | W3: 4.5 | X3: 70 | Y3: 65 | Z3: 260 | AA3: 39 | AC3: =IF(OR(L3="", AB3=""), 0, IF(L3="Découverte", KPI!$F$2, IF(L3="Essentiel", KPI!$F$3, IF(L3="Premium", KPI!$F$4, 0) ) ) ) -> 0 | AD3: {=IF(F3="", "", (T3 / 1.21) - IF(L3="Découverte", KPI!$C$2, IF(L3="Essentiel", KPI!$C$3, IF(L3="Premium", KPI!$C$4, 0) ) ) - N(X3) - N(AA3) - N(AC3) - IFERROR(INDEX(Stats!$G:$G, MATCH(DATE(YEAR(R3), MONTH(R3), 1), Stats!$A:$A, 0)), 35) )} -> 342.80785 | AH3: sct6isre8vahfts4ir6u9a5jj4@google.com | AI3: OK 2025-12-01 19:15 | AM3: 2025_0001
A4: Angélique Crucilla - Commune Fleurus | D4: FR | M4: 595 | AM4: 2025_0035
A5: Stocq Marie-Christine - police Bruneau | C5: 071/820161 | D5: FR | F5: 45673 | I5: Chemin de Mons 61, Fleurus | J5: B2B | L5: Premium | M5: 545 | T5: =M5 -> 545 | U5: 545 | V5: Abdel | W5: 4.5 | X5: 70 | Y5: 65 | Z5: 260 | AA5: 39 | AC5: =IF(OR(L5="", AB5=""), 0, IF(L5="Découverte", KPI!$F$2, IF(L5="Essentiel", KPI!$F$3, IF(L5="Premium", KPI!$F$4, 0) ) ) ) -> 0 | AD5: {=IF(F5="", "", (T5 / 1.21) - IF(L5="Découverte", KPI!$C$2, IF(L5="Essentiel", KPI!$C$3, IF(L5="Premium", KPI!$C$4, 0) ) ) - N(X5) - N(AA5) - N(AC5) - IFERROR(INDEX(Stats!$G:$G, MATCH(DATE(YEAR(R5), MONTH(R5), 1), Stats!$A:$A, 0)), 35) )} -> 213.91322 | AH5: t8hfdemg2ucfctt81b1f5qn8c0@google.com | AI5: OK 2025-12-01 19:15 | AM5: 2025_0002
A6: MIFRATEL | D6: FR | J6: B2B | M6: 859.1 | AM6: 2025_0036
A7: Natacha Gallo | B7: gallonatacha509@gmail.com | C7: 0472 04 16 34 | D7: FR | F7: 45682 | I7: Prestige du clothaire, Quévy | J7: Mariage | L7: Découverte | M7: 350 | N7: 80 | T7: =SUM(M7:N7) -> 430 | U7: =T7-S7 -> 430 | V7: Abdel | W7: 5.5 | X7: 70 | Y7: 86 | Z7: 344 | AA7: 51.6 | AC7: =IF(OR(L7="", AB7=""), 0, IF(L7="Découverte", KPI!$F$2, IF(L7="Essentiel", KPI!$F$3, IF(L7="Premium", KPI!$F$4, 0) ) ) ) -> 0 | AD7: {=IF(F7="", "", (T7 / 1.21) - IF(L7="Découverte", KPI!$C$2, IF(L7="Essentiel", KPI!$C$3, IF(L7="Premium", KPI!$C$4, 0) ) ) - N(X7) - N(AA7) - N(AC7) - IFERROR(INDEX(Stats!$G:$G, MATCH(DATE(YEAR(R7), MONTH(R7), 1), Stats!$A:$A, 0)), 35) )} -> 175.6519 | AH7: qtpq6pr8uro4osq6c8j4fupa3c@google.com | AI7: OK 2025-12-01 19:14 | AM7: 2025_0003
A8: Carole Crunelle | B8: carole.crunelle@hotmail.com | C8: 0476 856 004 | D8: FR | F8: 45738 | I8: Rue de Tournai 188, 7333 Saint-Ghislain | J8: Mariage | L8: Premium | M8: 500 | N8: 80 | T8: =SUM(M8:N8) -> 580 | U8: =T8-S8 -> 580 | V8: Abdel | W8: 5 | X8: 70 | Y8: 79 | Z8: 316 | AA8: 47.4 | AC8: =IF(OR(L8="", AB8=""), 0, IF(L8="Découverte", KPI!$F$2, IF(L8="Essentiel", KPI!$F$3, IF(L8="Premium", KPI!$F$4, 0) ) ) ) -> 0 | AD8: {=IF(F8="", "", (T8 / 1.21) - IF(L8="Découverte", KPI!$C$2, IF(L8="Essentiel", KPI!$C$3, IF(L8="Premium", KPI!$C$4, 0) ) ) - N(X8) - N(AA8) - N(AC8) - IFERROR(INDEX(Stats!$G:$G, MATCH(DATE(YEAR(R8), MONTH(R8), 1), Stats!$A:$A, 0)), 35) )} -> 234.43884 | AH8: voku23g04gc3ftjs94t9njrlgo@google.com | AI8: OK 2025-12-01 19:12 | AK8: Sent | AM8: 2025_0011
A9: Catherine Onclin | B9: catherine.onclin@gmail.com | C9: 0470 50 44 32 | D9: FR | F9: 45759 | I9: Hasselt (Tiendschuur Herkenrode) | J9: Mariage | L9: Premium | M9: 500 | N9: 80 | T9: =SUM(M9:N9) -> 580 | U9: =T9-S9 -> 580 | V9: Abdel | W9: 5.5 | X9: 70 | Y9: 86 | Z9: 344 | AA9: 51.6 | AC9: =IF(OR(L9="", AB9=""), 0, IF(L9="Découverte", KPI!$F$2, IF(L9="Essentiel", KPI!$F$3, IF(L9="Premium", KPI!$F$4, 0) ) ) ) -> 0 | AD9: {=IF(F9="", "", (T9 / 1.21) - IF(L9="Découverte", KPI!$C$2, IF(L9="Essentiel", KPI!$C$3, IF(L9="Premium", KPI!$C$4, 0) ) ) - N(X9) - N(AA9) - N(AC9) - IFERROR(INDEX(Stats!$G:$G, MATCH(DATE(YEAR(R9), MONTH(R9), 1), Stats!$A:$A, 0)), 35) )} -> 230.23884 | AH9: 8siq7u4sh6ggev6knle9psg2n4@google.com | AI9: OK 2025-12-01 19:11 | AK9: Sent | AM9: 2025_0015
A10: Jordan Farias | B10: jordan.farias@verisure.be | C10: 0471621626 | D10: FR | F10: 45759 | I10: Rue Lannoy 145, 7740 Pecq | L10: Premium | M10: 200 | N10: 110 | T10: =SUM(M10:N10) -> 310 | U10: =T10-S10 -> 310 | V10: Abdel | W10: 6 | X10: 70 | Y10: 95 | Z10: 380 | AA10: 57 | AC10: =IF(OR(L10="", AB10=""), 0, IF(L10="Découverte", KPI!$F$2, IF(L10="Essentiel", KPI!$F$3, IF(L10="Premium", KPI!$F$4, 0) ) ) ) -> 0 | AD10: {=IF(F10="", "", (T10 / 1.21) - IF(L10="Découverte", KPI!$C$2, IF(L10="Essentiel", KPI!$C$3, IF(L10="Premium", KPI!$C$4, 0) ) ) - N(X10) - N(AA10) - N(AC10) - IFERROR(INDEX(Stats!$G:$G, MATCH(DATE(YEAR(R10), MONTH(R10), 1), Stats!$A:$A, 0)), 35) )} -> 1.6983471 | AH10: op3lh8589jogdlqsl3k22dgdeo@google.com | AI10: OK 2025-12-01 19:25 | AK10: Sent | AM10: 2024_0001
A11: Maeva Dos Santos | B11: maevadd2@outlook.fr | C11: 0033 6 16 02 25 29 | D11: FR | F11: 45773 | I11: salle alta ripa, Avelgem | J11: Mariage | L11: Premium | M11: 500 | N11: 100 | T11: =SUM(M11:N11) -> 600 | U11: =T11-S11 -> 600 | V11: Abdel | W11: 6 | X11: 70 | Y11: 91 | Z11: 364 | AA11: 54.6 | AC11: =IF(OR(L11="", AB11=""), 0, IF(L11="Découverte", KPI!$F$2, IF(L11="Essentiel", KPI!$F$3, IF(L11="Premium", KPI!$F$4, 0) ) ) ) -> 0 | AD11: {=IF(F11="", "", (T11 / 1.21) - IF(L11="Découverte", KPI!$C$2, IF(L11="Essentiel", KPI!$C$3, IF(L11="Premium", KPI!$C$4, 0) ) ) - N(X11) - N(AA11) - N(AC11) - IFERROR(INDEX(Stats!$G:$G, MATCH(DATE(YEAR(R11), MONTH(R11), 1), Stats!$A:$A, 0)), 35) )} -> 243.76777 | AH11: ou1tjsn0jb2u3c62dlcjg4atr4@google.com | AI11: OK 2025-12-01 19:09 | AM11: 2025_0017
A12: Lyna Botte | B12: bottelyna27@gmail.com | C12: 0485 69 22 87 | D12: FR | F12: 45780 | I12: Salle The villa Event | J12: Mariage | L12: Premium | M12: 500 | T12: =SUM(M12:N12) -> 500 | U12: =T12-S12 -> 500 | V12: Abdel | W12: 2 | X12: 70 | Y12: 8 | Z12: 32 | AA12: 4.8 | AC12: =IF(OR(L12="", AB12=""), 0, IF(L12="Découverte", KPI!$F$2, IF(L12="Essentiel", KPI!$F$3, IF(L12="Premium", KPI!$F$4, 0) ) ) ) -> 0 | AD12: {=IF(F12="", "", (T12 / 1.21) - IF(L12="Découverte", KPI!$C$2, IF(L12="Essentiel", KPI!$C$3, IF(L12="Premium", KPI!$C$4, 0) ) ) - N(X12) - N(AA12) - N(AC12) - IFERROR(INDEX(Stats!$G:$G, MATCH(DATE(YEAR(R12), MONTH(R12), 1), Stats!$A:$A, 0)), 35) )} -> 210.92314 | AH12: mju0pfaqqciofm6k92f94vibis@google.com | AI12: OK 2025-12-01 19:08 | AM12: 2025_0020
A13: Serge Skrzypek | B13: Skrzypek_s@hotmail.com | C13: 0474450223 | D13: FR | F13: 45780 | I13: 210 rue Alphonse Allard, 1420 Braine L'Alleud | J13: Mariage | L13: Premium | M13: 500 | N13: 35 | T13: =SUM(M13:N13) -> 535 | U13: =T13-S13 -> 535 | V13: Abdel | W13: 3 | X13: 70 | Y13: 27 | Z13: 108 | AA13: 16.2 | AC13: =IF(OR(L13="", AB13=""), 0, IF(L13="Découverte", KPI!$F$2, IF(L13="Essentiel", KPI!$F$3, IF(L13="Premium", KPI!$F$4, 0) ) ) ) -> 0 | AD13: {=IF(F13="", "", (T13 / 1.21) - IF(L13="Découverte", KPI!$C$2, IF(L13="Essentiel", KPI!$C$3, IF(L13="Premium", KPI!$C$4, 0) ) ) - N(X13) - N(AA13) - N(AC13) - IFERROR(INDEX(Stats!$G:$G, MATCH(DATE(YEAR(R13), MONTH(R13), 1), Stats!$A:$A, 0)), 35) )} -> 228.44876 | AH13: 0m6f00d2p66tgi3vv2cjrlvgjo@google.com | AI13: OK 2025-12-01 19:12 | AL13: 2025_0010 | AM13: 2025_0021
A14: Mike et Julie Deboeck | B14: vandenbemden_julie@outlook.com | C14: 0477783468 | D14: FR | F14: 45787 | I14: La ferme de Bertinchamps, Ophain | J14: Mariage | L14: Premium | M14: 500 | N14: 50 | T14: =SUM(M14:N14) -> 550 | U14: =T14-S14 -> 550 | V14: Abdel | W14: 3 | X14: 70 | Y14: 30 | Z14: 120 | AA14: 18 | AC14: =IF(OR(L14="", AB14=""), 0, IF(L14="Découverte", KPI!$F$2, IF(L14="Essentiel", KPI!$F$3, IF(L14="Premium", KPI!$F$4, 0) ) ) ) -> 0 | AD14: {=IF(F14="", "", (T14 / 1.21) - IF(L14="Découverte", KPI!$C$2, IF(L14="Essentiel", KPI!$C$3, IF(L14="Premium", KPI!$C$4, 0) ) ) - N(X14) - N(AA14) - N(AC14) - IFERROR(INDEX(Stats!$G:$G, MATCH(DATE(YEAR(R14), MONTH(R14), 1), Stats!$A:$A, 0)), 35) )} -> 239.04545 | AH14: dqje0kkk2d3o655gr9h2erjs5c@google.com | AI14: OK 2025-12-01 19:07 | AM14: 2025_0024
A15: Abdelrani bousnina | B15: Abdelranibousnina@gmail.com | C15: 0484 067 079 | D15: FR | F15: 45787 | I15: Hendrik Kuijpersstraat 49, 2640 Mortsel | J15: Mariage | L15: Premium | M15: 500 | N15: 80 | T15: =SUM(M15:N15) -> 580 | U15: =T15-S15 -> 580 | V15: Abdel | W15: 4 | X15: 70 | Y15: 55 | Z15: 220 | AA15: 33 | AC15: =IF(OR(L15="", AB15=""), 0, IF(L15="Découverte", KPI!$F$2, IF(L15="Essentiel", KPI!$F$3, IF(L15="Premium", KPI!$F$4, 0) ) ) ) -> 0 | AD15: {=IF(F15="", "", (T15 / 1.21) - IF(L15="Découverte", KPI!$C$2, IF(L15="Essentiel", KPI!$C$3, IF(L15="Premium", KPI!$C$4, 0) ) ) - N(X15) - N(AA15) - N(AC15) - IFERROR(INDEX(Stats!$G:$G, MATCH(DATE(YEAR(R15), MONTH(R15), 1), Stats!$A:$A, 0)), 35) )} -> 248.83884 | AH15: 8hol2v8lrsg60g2tk172hcb65k@google.com | AI15: OK 2025-12-01 19:08 | AL15: 2025_0022 | AM15: 2025_0025
A16: Annick Allard | B16: Annickallard1985@gmail.com | C16: 0471 08 94 51 | D16: FR | F16: 45801 | I16: Avenue Jean-François Debecker 54B, 1200 Woluwe-Saint-Lambert | J16: Mariage | L16: Essentiel | M16: 450 | N16: 50 | T16: =SUM(M16:N16) -> 500 | U16: =T16-S16 -> 500 | V16: Abdel | W16: 3 | X16: 70 | Y16: 15 | Z16: 60 | AA16: 9 | AC16: =IF(OR(L16="", AB16=""), 0, IF(L16="Découverte", KPI!$F$2, IF(L16="Essentiel", KPI!$F$3, IF(L16="Premium", KPI!$F$4, 0) ) ) ) -> 0 | AD16: {=IF(F16="", "", (T16 / 1.21) - IF(L16="Découverte", KPI!$C$2, IF(L16="Essentiel", KPI!$C$3, IF(L16="Premium", KPI!$C$4, 0) ) ) - N(X16) - N(AA16) - N(AC16) - IFERROR(INDEX(Stats!$G:$G, MATCH(DATE(YEAR(R16), MONTH(R16), 1), Stats!$A:$A, 0)), 35) )} -> 252.97314 | AH16: ech3tbfs4r0kljmsggbf1eq8i8@google.com | AI16: OK 2025-12-01 19:14 | AL16: 2025_0004 | AM16: 2025_0030
A17: Ioan Taziana | B17: decamk.tiziana@gmail.com | C17: 0499 32 24 98 | D17: FR | F17: 45801 | I17: rue des brasseries 10, 7170 Manage | J17: Mariage | L17: Essentiel | M17: 450 | N17: 50 | T17: =SUM(M17:N17) -> 500 | U17: =T17-S17 -> 500 | V17: Abdel | W17: 4 | X17: 70 | Y17: 52 | Z17: 208 | AA17: 31.2 | AC17: =IF(OR(L17="", AB17=""), 0, IF(L17="Découverte", KPI!$F$2, IF(L17="Essentiel", KPI!$F$3, IF(L17="Premium", KPI!$F$4, 0) ) ) ) -> 0 | AD17: {=IF(F17="", "", (T17 / 1.21) - IF(L17="Découverte", KPI!$C$2, IF(L17="Essentiel", KPI!$C$3, IF(L17="Premium", KPI!$C$4, 0) ) ) - N(X17) - N(AA17) - N(AC17) - IFERROR(INDEX(Stats!$G:$G, MATCH(DATE(YEAR(R17), MONTH(R17), 1), Stats!$A:$A, 0)), 35) )} -> 230.77314 | AH17: 2tkfj4g8sjt8obb2j0urr77598@google.com | AI17: OK 2025-12-01 19:06 | AL17: 2025_0026 | AM17: 2025_0031
A18: Didier Blesin | B18: didier.blesin@gmail.com | C18: 0497 41 14 73 | D18: FR | F18: 45801 | I18: Chaussée de bruxelles 111, 1310 La Hulpe | J18: Mariage | L18: Premium | M18: 500 | N18: 50 | T18: =SUM(M18:N18) -> 550 | U18: =T18-S18 -> 550 | V18: Abdel | W18: 4 | X18: 70 | Y18: 32 | Z18: 128 | AA18: 19.2 | AC18: =IF(OR(L18="", AB18=""), 0, IF(L18="Découverte", KPI!$F$2, IF(L18="Essentiel", KPI!$F$3, IF(L18="Premium", KPI!$F$4, 0) ) ) ) -> 0 | AD18: {=IF(F18="", "", (T18 / 1.21) - IF(L18="Découverte", KPI!$C$2, IF(L18="Essentiel", KPI!$C$3, IF(L18="Premium", KPI!$C$4, 0) ) ) - N(X18) - N(AA18) - N(AC18) - IFERROR(INDEX(Stats!$G:$G, MATCH(DATE(YEAR(R18), MONTH(R18), 1), Stats!$A:$A, 0)), 35) )} -> 237.84545 | AH18: 9k5vis2g0ic9glbnn5l0k5ior0@google.com | AI18: OK 2025-12-01 19:13 | AL18: 2025_0007 | AM18: 2025_0032
A19: Samira Natiq | B19: samiranatiq@gmail.com | C19: 0485037895 | D19: FR | F19: 45822 | I19: La Louvière | J19: Mariage | L19: Essentiel | M19: 450 | N19: 50 | T19: =SUM(M19:N19) -> 500 | U19: =T19-S19 -> 500 | V19: Abdel | W19: 4 | X19: 70 | Y19: 53 | Z19: 212 | AA19: 31.8 | AC19: =IF(OR(L19="", AB19=""), 0, IF(L19="Découverte", KPI!$F$2, IF(L19="Essentiel", KPI!$F$3, IF(L19="Premium", KPI!$F$4, 0) ) ) ) -> 0 | AD19: {=IF(F19="", "", (T19 / 1.21) - IF(L19="Découverte", KPI!$C$2, IF(L19="Essentiel", KPI!$C$3, IF(L19="Premium", KPI!$C$4, 0) ) ) - N(X19) - N(AA19) - N(AC19) - IFERROR(INDEX(Stats!$G:$G, MATCH(DATE(YEAR(R19), MONTH(R19), 1), Stats!$A:$A, 0)), 35) )} -> 230.17314 | AH19: 8eh62mlikvfitg943t7b72sctg@google.com | AI19: OK 2025-12-01 19:12 | AL19: 2025_0008 | AM19: 2025_0034
A20: Meli Meli | D20: FR | F20: 45828 | J20: B2B | L20: Premium | M20: 500 | T20: =SUM(M20:N20) -> 500 | U20: =T20-S20 -> 500 | V20: Abdel | X20: 70 | AA20: =IF(Z20=0,"", Z20 * 0.15) | AC20: =IF(OR(L20="", AB20=""), 0, IF(L20="Découverte", KPI!$F$2, IF(L20="Essentiel", KPI!$F$3, IF(L20="Premium", KPI!$F$4, 0) ) ) ) -> 0 | AD20: {=IF(F20="", "", (T20 / 1.21) - IF(L20="Découverte", KPI!$C$2, IF(L20="Essentiel", KPI!$C$3, IF(L20="Premium", KPI!$C$4, 0) ) ) - N(X20) - N(AA20) - N(AC20) - IFERROR(INDEX(Stats!$G:$G, MATCH(DATE(YEAR(R20), MONTH(R20), 1), Stats!$A:$A, 0)), 35) )} -> 215.72314 | AH20: a580dr3lnta2gc398qf7a4qeug@google.com | AI20: OK 2025-11-21 21:18
A21: Meli Meli | D21: FR | F21: 45829 | J21: B2B | L21: Premium | M21: 500 | T21: =SUM(M21:N21) -> 500 | U21: =T21-S21 -> 500 | V21: Abdel | X21: 70 | AA21: =IF(Z21=0,"", Z21 * 0.15) | AC21: =IF(OR(L21="", AB21=""), 0, IF(L21="Découverte", KPI!$F$2, IF(L21="Essentiel", KPI!$F$3, IF(L21="Premium", KPI!$F$4, 0) ) ) ) -> 0 | AD21: {=IF(F21="", "", (T21 / 1.21) - IF(L21="Découverte", KPI!$C$2, IF(L21="Essentiel", KPI!$C$3, IF(L21="Premium", KPI!$C$4, 0) ) ) - N(X21) - N(AA21) - N(AC21) - IFERROR(INDEX(Stats!$G:$G, MATCH(DATE(YEAR(R21), MONTH(R21), 1), Stats!$A:$A, 0)), 35) )} -> 215.72314 | AH21: a1vjn8877eje74j131lmvrgqks@google.com | AI21: OK 2025-11-21 21:18
A22: Fatima | B22: Tahiri-fatima@hotmail.com | C22: 0484761578 | D22: FR | F22: 45832 | I22: Oudstrijderslaan 200, 1140 Evere | J22: Mariage | L22: Découverte | M22: 350 | N22: 50 | T22: =SUM(M22:N22) -> 400 | U22: =T22-S22 -> 400 | V22: Abdel | W22: 3 | X22: 70 | Y22: 15 | Z22: 60 | AA22: 9 | AC22: =IF(OR(L22="", AB22=""), 0, IF(L22="Découverte", KPI!$F$2, IF(L22="Essentiel", KPI!$F$3, IF(L22="Premium", KPI!$F$4, 0) ) ) ) -> 0 | AD22: {=IF(F22="", "", (T22 / 1.21) - IF(L22="Découverte", KPI!$C$2, IF(L22="Essentiel", KPI!$C$3, IF(L22="Premium", KPI!$C$4, 0) ) ) - N(X22) - N(AA22) - N(AC22) - IFERROR(INDEX(Stats!$G:$G, MATCH(DATE(YEAR(R22), MONTH(R22), 1), Stats!$A:$A, 0)), 35) )} -> 193.45851 | AH22: omujkk1igs6bb0rhvimuudmhvc@google.com | AI22: OK 2025-12-01 19:26 | AM22: 2024_0002
A23: Magali Rosa Lopez | B23: lopez4781@hotmail.com | C23: 0479 84 65 30 | D23: FR | F23: 45833 | I23: Place du Mole 11, Braine-L'alleud | J23: Mariage | L23: Premium | M23: 400 | T23: =SUM(M23:N23) -> 400 | U23: =T23-S23 -> 400 | V23: Abdel | W23: 3.5 | X23: 70 | Y23: 30 | Z23: 120 | AA23: 18 | AC23: =IF(OR(L23="", AB23=""), 0, IF(L23="Découverte", KPI!$F$2, IF(L23="Essentiel", KPI!$F$3, IF(L23="Premium", KPI!$F$4, 0) ) ) ) -> 0 | AD23: {=IF(F23="", "", (T23 / 1.21) - IF(L23="Découverte", KPI!$C$2, IF(L23="Essentiel", KPI!$C$3, IF(L23="Premium", KPI!$C$4, 0) ) ) - N(X23) - N(AA23) - N(AC23) - IFERROR(INDEX(Stats!$G:$G, MATCH(DATE(YEAR(R23), MONTH(R23), 1), Stats!$A:$A, 0)), 35) )} -> 115.07851 | AH23: a7egjnkibo8vjv91ltjqklona4@google.com | AI23: OK 2025-12-01 19:26 | AL23: 2025_0027 | AM23: 2024_0003
A24: Jennifer Jacquemin | B24: jenniferjacquemin@outlook.be | C24: 0492 96 03 66 | D24: FR | F24: 45857 | I24: Rue des chapelain 6, 4000 Liège | J24: Mariage | L24: Premium | M24: 500 | N24: 100 | T24: =SUM(M24:N24) -> 600 | U24: =T24-S24 -> 600 | V24: Abdel | W24: 6.5 | X24: 70 | Y24: 103 | Z24: 412 | AA24: 61.8 | AC24: =IF(OR(L24="", AB24=""), 0, IF(L24="Découverte", KPI!$F$2, IF(L24="Essentiel", KPI!$F$3, IF(L24="Premium", KPI!$F$4, 0) ) ) ) -> 0 | AD24: {=IF(F24="", "", (T24 / 1.21) - IF(L24="Découverte", KPI!$C$2, IF(L24="Essentiel", KPI!$C$3, IF(L24="Premium", KPI!$C$4, 0) ) ) - N(X24) - N(AA24) - N(AC24) - IFERROR(INDEX(Stats!$G:$G, MATCH(DATE(YEAR(R24), MONTH(R24), 1), Stats!$A:$A, 0)), 35) )} -> 236.56777 | AH24: r94e53c6vics8vrlj4le27373o@google.com | AI24: OK 2025-12-01 19:05 | AL24: 2025_0029 | AM24: 2025_0037
A25: Mathilde Debay | B25: mathilde.debay@gmail.com | C25: 0478 92 84 07 | D25: FR | F25: 45857 | I25: Rue du parc 4, 4577 Modave | J25: Mariage | L25: Premium | M25: 500 | N25: 120 | T25: =SUM(M25:N25) -> 620 | U25: =T25-S25 -> 620 | V25: Abdel | W25: 7.5 | X25: 70 | Y25: 110 | Z25: 440 | AA25: 66 | AC25: =IF(OR(L25="", AB25=""), 0, IF(L25="Découverte", KPI!$F$2, IF(L25="Essentiel", KPI!$F$3, IF(L25="Premium", KPI!$F$4, 0) ) ) ) -> 0 | AD25: {=IF(F25="", "", (T25 / 1.21) - IF(L25="Découverte", KPI!$C$2, IF(L25="Essentiel", KPI!$C$3, IF(L25="Premium", KPI!$C$4, 0) ) ) - N(X25) - N(AA25) - N(AC25) - IFERROR(INDEX(Stats!$G:$G, MATCH(DATE(YEAR(R25), MONTH(R25), 1), Stats!$A:$A, 0)), 35) )} -> 248.89669 | AH25: ba31nuhi5p57glrmq85m8octh0@google.com | AI25: OK 2025-12-01 19:04 | AL25: 2025_0033 | AM25: 2025_0038
A26: Laura Kowalsi | B26: laura.kowalski@hotmail.fr | C26: 0033615253010 | D26: FR | F26: 45864 | I26: 214 rue Roger salengro, 59590 raismes | J26: Mariage | L26: Premium | M26: 500 | N26: 125 | T26: =SUM(M26:N26) -> 625 | U26: =T26-S26 -> 625 | V26: Abdel | W26: 6.5 | X26: 70 | Y26: 117 | Z26: 468 | AA26: 70.2 | AC26: =IF(OR(L26="", AB26=""), 0, IF(L26="Découverte", KPI!$F$2, IF(L26="Essentiel", KPI!$F$3, IF(L26="Premium", KPI!$F$4, 0) ) ) ) -> 0 | AD26: {=IF(F26="", "", (T26 / 1.21) - IF(L26="Découverte", KPI!$C$2, IF(L26="Essentiel", KPI!$C$3, IF(L26="Premium", KPI!$C$4, 0) ) ) - N(X26) - N(AA26) - N(AC26) - IFERROR(INDEX(Stats!$G:$G, MATCH(DATE(YEAR(R26), MONTH(R26), 1), Stats!$A:$A, 0)), 35) )} -> 248.82893 | AH26: 3l3p48p658l0qru1jn0fs0jomo@google.com | AI26: OK 2025-12-01 19:11 | AL26: 2025_0013 | AM26: 2025_0039
A27: Kevin Ladeuze | B27: k.ladeuze@outlook.com | C27: 0494361803 | D27: FR | F27: 45877 | I27: rue Grégoire jurion 22, 7120 vellereille-les-brayeux | J27: Mariage | L27: Premium | M27: 500 | N27: 70 | T27: =SUM(M27:N27) -> 570 | U27: =T27-S27 -> 570 | V27: Abdel | W27: 5 | X27: 70 | Y27: 69 | Z27: 276 | AA27: 41.4 | AC27: =IF(OR(L27="", AB27=""), 0, IF(L27="Découverte", KPI!$F$2, IF(L27="Essentiel", KPI!$F$3, IF(L27="Premium", KPI!$F$4, 0) ) ) ) -> 0 | AD27: {=IF(F27="", "", (T27 / 1.21) - IF(L27="Découverte", KPI!$C$2, IF(L27="Essentiel", KPI!$C$3, IF(L27="Premium", KPI!$C$4, 0) ) ) - N(X27) - N(AA27) - N(AC27) - IFERROR(INDEX(Stats!$G:$G, MATCH(DATE(YEAR(R27), MONTH(R27), 1), Stats!$A:$A, 0)), 35) )} -> 232.17438 | AH27: rqgp73fd6udgfsmc7t1738me5s@google.com | AI27: OK 2025-12-01 18:57 | AM27: 2025_0042
A28: Olivier Vanhuysse | B28: ovanhuysse@gmail.com | C28: 0473 30 16 86 | D28: FR | F28: 45878 | I28: Rue de la longue semaine, 1460 Ittre | J28: Mariage | L28: Premium | M28: 500 | N28: 70 | T28: =SUM(M28:N28) -> 570 | U28: =T28-S28 -> 570 | V28: Abdel | W28: 3 | X28: 70 | Y28: 29 | Z28: 116 | AA28: 17.4 | AC28: =IF(OR(L28="", AB28=""), 0, IF(L28="Découverte", KPI!$F$2, IF(L28="Essentiel", KPI!$F$3, IF(L28="Premium", KPI!$F$4, 0) ) ) ) -> 0 | AD28: {=IF(F28="", "", (T28 / 1.21) - IF(L28="Découverte", KPI!$C$2, IF(L28="Essentiel", KPI!$C$3, IF(L28="Premium", KPI!$C$4, 0) ) ) - N(X28) - N(AA28) - N(AC28) - IFERROR(INDEX(Stats!$G:$G, MATCH(DATE(YEAR(R28), MONTH(R28), 1), Stats!$A:$A, 0)), 35) )} -> 256.17438 | AH28: 5frs8959qd51eovoq5oltr2pvc@google.com | AI28: OK 2025-12-01 19:12 | AL28: 2025_0009 | AM28: 2025_0043
A29: Fortuna Giovanni | B29: fortunagiovanni@hotmail.com | C29: 0472261163 | D29: FR | F29: 45878 | I29: 83 voie des fosses, 4607 dalhem | J29: Mariage | L29: Premium | M29: 600 | N29: 100 | T29: =SUM(M29:N29) -> 700 | U29: =T29-S29 -> 700 | V29: Abdel | W29: 7 | X29: 70 | Y29: 115 | Z29: 460 | AA29: 69 | AC29: =IF(OR(L29="", AB29=""), 0, IF(L29="Découverte", KPI!$F$2, IF(L29="Essentiel", KPI!$F$3, IF(L29="Premium", KPI!$F$4, 0) ) ) ) -> 0 | AD29: {=IF(F29="", "", (T29 / 1.21) - IF(L29="Découverte", KPI!$C$2, IF(L29="Essentiel", KPI!$C$3, IF(L29="Premium", KPI!$C$4, 0) ) ) - N(X29) - N(AA29) - N(AC29) - IFERROR(INDEX(Stats!$G:$G, MATCH(DATE(YEAR(R29), MONTH(R29), 1), Stats!$A:$A, 0)), 35) )} -> 312.0124 | AH29: q7v7c1gh8ued6dojf497pjd7h0@google.com | AI29: OK 2025-12-01 18:56 | AL29: 2025_0044 | AM29: 2025_0045
A30: Alexia Cuffaro | C30: 0492 57 14 99 | D30: FR | F30: 45878 | I30: Rue docteur E. Neuville 17, 4530 Villers le Bouillet | J30: Mariage | L30: Premium | M30: 650 | N30: 100 | T30: =SUM(M30:N30) -> 750 | U30: =T30-S30 -> 750 | V30: Abdel | W30: 6 | X30: 70 | Y30: 88 | Z30: 352 | AA30: 52.8 | AC30: =IF(OR(L30="", AB30=""), 0, IF(L30="Découverte", KPI!$F$2, IF(L30="Essentiel", KPI!$F$3, IF(L30="Premium", KPI!$F$4, 0) ) ) ) -> 0 | AD30: {=IF(F30="", "", (T30 / 1.21) - IF(L30="Découverte", KPI!$C$2, IF(L30="Essentiel", KPI!$C$3, IF(L30="Premium", KPI!$C$4, 0) ) ) - N(X30) - N(AA30) - N(AC30) - IFERROR(INDEX(Stats!$G:$G, MATCH(DATE(YEAR(R30), MONTH(R30), 1), Stats!$A:$A, 0)), 35) )} -> 369.53471 | AH30: 45mvgl689is6kanieu791ik2nk@google.com | AI30: OK 2025-11-22 13:01
A31: Clément Picard | B31: yaelle.clement.home@gmail.com | C31: 0033 750381771 | D31: FR | F31: 45885 | I31: Château de Bac Saint Maur, Sailly sur la Lys | J31: Mariage | L31: Essentiel | M31: 450 | N31: 130 | T31: =SUM(M31:N31) -> 580 | U31: =T31-S31 -> 580 | V31: Abdel | W31: 7.5 | X31: 70 | Y31: 132 | Z31: 528 | AA31: 79.2 | AC31: =IF(OR(L31="", AB31=""), 0, IF(L31="Découverte", KPI!$F$2, IF(L31="Essentiel", KPI!$F$3, IF(L31="Premium", KPI!$F$4, 0) ) ) ) -> 0 | AD31: {=IF(F31="", "", (T31 / 1.21) - IF(L31="Découverte", KPI!$C$2, IF(L31="Essentiel", KPI!$C$3, IF(L31="Premium", KPI!$C$4, 0) ) ) - N(X31) - N(AA31) - N(AC31) - IFERROR(INDEX(Stats!$G:$G, MATCH(DATE(YEAR(R31), MONTH(R31), 1), Stats!$A:$A, 0)), 35) )} -> 248.88884 | AH31: 6mjjfbvf15rrv3i73lc7o8avm0@google.com | AI31: OK 2025-12-01 18:56 | AM31: 2025_0047
A32: Melissa Dasouza | B32: melissa.dasouza60@orange.fr | C32: 0685 63 24 67 | D32: FR | F32: 45885 | I32: Éteignières, 08260, France | J32: Mariage | L32: Premium | M32: 500 | N32: 140 | T32: =SUM(M32:N32) -> 640 | U32: =T32-S32 -> 640 | V32: Abdel | W32: 8 | X32: 70 | Y32: 133 | Z32: 532 | AA32: 79.8 | AC32: =IF(OR(L32="", AB32=""), 0, IF(L32="Découverte", KPI!$F$2, IF(L32="Essentiel", KPI!$F$3, IF(L32="Premium", KPI!$F$4, 0) ) ) ) -> 0 | AD32: {=IF(F32="", "", (T32 / 1.21) - IF(L32="Découverte", KPI!$C$2, IF(L32="Essentiel", KPI!$C$3, IF(L32="Premium", KPI!$C$4, 0) ) ) - N(X32) - N(AA32) - N(AC32) - IFERROR(INDEX(Stats!$G:$G, MATCH(DATE(YEAR(R32), MONTH(R32), 1), Stats!$A:$A, 0)), 35) )} -> 251.62562 | AH32: m2f093aot0iv83is8lb43cj08k@google.com | AI32: OK 2025-12-01 18:55 | AM32: 2025_0048
A33: Frederique Verden | B33: verden.fred@gmail.com | C33: 0493 54 56 53 | D33: FR | F33: 45885 | I33: Jozef Mertensstraat 140, 1702 Dilbeek | J33: Mariage | L33: Essentiel | M33: 450 | N33: 50 | T33: =SUM(M33:N33) -> 500 | U33: =T33-S33 -> 500 | V33: Abdel | W33: 2.5 | X33: 70 | Y33: 20 | Z33: 80 | AA33: 12 | AC33: =IF(OR(L33="", AB33=""), 0, IF(L33="Découverte", KPI!$F$2, IF(L33="Essentiel", KPI!$F$3, IF(L33="Premium", KPI!$F$4, 0) ) ) ) -> 0 | AD33: {=IF(F33="", "", (T33 / 1.21) - IF(L33="Découverte", KPI!$C$2, IF(L33="Essentiel", KPI!$C$3, IF(L33="Premium", KPI!$C$4, 0) ) ) - N(X33) - N(AA33) - N(AC33) - IFERROR(INDEX(Stats!$G:$G, MATCH(DATE(YEAR(R33), MONTH(R33), 1), Stats!$A:$A, 0)), 35) )} -> 249.97314 | AH33: d6d118gbchdm1m5qsbfjgs8qlg@google.com | AI33: OK 2025-12-01 19:26 | AM33: 2024_0003
A34: Sephora Karmaoui | C34: 0492 54 28 26 | D34: FR | F34: 45891 | J34: Mariage | L34: Premium | M34: 500 | T34: =SUM(M34:N34) -> 500 | U34: =T34-S34 -> 500 | V34: Abdel | X34: 70 | AA34: =IF(Z34=0,"", Z34 * 0.15) | AC34: =IF(OR(L34="", AB34=""), 0, IF(L34="Découverte", KPI!$F$2, IF(L34="Essentiel", KPI!$F$3, IF(L34="Premium", KPI!$F$4, 0) ) ) ) -> 0 | AD34: {=IF(F34="", "", (T34 / 1.21) - IF(L34="Découverte", KPI!$C$2, IF(L34="Essentiel", KPI!$C$3, IF(L34="Premium", KPI!$C$4, 0) ) ) - N(X34) - N(AA34) - N(AC34) - IFERROR(INDEX(Stats!$G:$G, MATCH(DATE(YEAR(R34), MONTH(R34), 1), Stats!$A:$A, 0)), 35) )} -> 215.72314 | AH34: m39hf7euq7elo338k851sng218@google.com | AI34: OK 2025-11-21 21:18
A35: Juliette Gomis | B35: juliette.gomis26@gmail.com | C35: 0033784727595 | D35: FR | F35: 45892 | I35: Gasthuisstraat 57, 8970 Poperinge | J35: Mariage | L35: Essentiel | M35: 450 | N35: 130 | T35: =SUM(M35:N35) -> 580 | U35: =T35-S35 -> 580 | V35: Abdel | W35: 7.5 | X35: 70 | Y35: 134 | Z35: 536 | AA35: 80.4 | AC35: =IF(OR(L35="", AB35=""), 0, IF(L35="Découverte", KPI!$F$2, IF(L35="Essentiel", KPI!$F$3, IF(L35="Premium", KPI!$F$4, 0) ) ) ) -> 0 | AD35: {=IF(F35="", "", (T35 / 1.21) - IF(L35="Découverte", KPI!$C$2, IF(L35="Essentiel", KPI!$C$3, IF(L35="Premium", KPI!$C$4, 0) ) ) - N(X35) - N(AA35) - N(AC35) - IFERROR(INDEX(Stats!$G:$G, MATCH(DATE(YEAR(R35), MONTH(R35), 1), Stats!$A:$A, 0)), 35) )} -> 247.68884 | AH35: j6q8gdnrjlfc97l4mu3aic711o@google.com | AI35: OK 2025-12-01 19:10 | AL35: 2025_0016 | AM35: 2025_0049
A36: Israa AL OUBAYDI | B36: isra.aloubaydi@gmail.com | C36: 0483 26 51 63 | D36: FR | F36: 45893 | I36: Broekstraat 77, 1831 Machelen | J36: Mariage | L36: Essentiel | M36: 450 | N36: 90 | T36: =SUM(M36:N36) -> 540 | U36: =T36-S36 -> 540 | V36: Abdel | W36: 3 | X36: 70 | Y36: 22 | Z36: 88 | AA36: 13.2 | AC36: =IF(OR(L36="", AB36=""), 0, IF(L36="Découverte", KPI!$F$2, IF(L36="Essentiel", KPI!$F$3, IF(L36="Premium", KPI!$F$4, 0) ) ) ) -> 0 | AD36: {=IF(F36="", "", (T36 / 1.21) - IF(L36="Découverte", KPI!$C$2, IF(L36="Essentiel", KPI!$C$3, IF(L36="Premium", KPI!$C$4, 0) ) ) - N(X36) - N(AA36) - N(AC36) - IFERROR(INDEX(Stats!$G:$G, MATCH(DATE(YEAR(R36), MONTH(R36), 1), Stats!$A:$A, 0)), 35) )} -> 281.83099 | AH36: 17k7k7fb7qni1mra3cb07qft9g@google.com | AI36: OK 2025-12-01 18:56 | AL36: 2025_0046 | AM36: 2025_0050
A37: Melanie Amichi | B37: Defretinmelanie@gmail.com | C37: 06 020 703 40 | D37: FR | F37: 45899 | I37: Domaine de la cendrée, Harnes | J37: Mariage | L37: Decouverte | M37: 400 | N37: 100 | T37: =SUM(M37:N37) -> 500 | U37: =T37-S37 -> 500 | V37: Abdel | W37: 7 | X37: 70 | Y37: 128 | Z37: 512 | AA37: 76.8 | AC37: =IF(OR(L37="", AB37=""), 0, IF(L37="Découverte", KPI!$F$2, IF(L37="Essentiel", KPI!$F$3, IF(L37="Premium", KPI!$F$4, 0) ) ) ) -> 0 | AD37: {=IF(F37="", "", (T37 / 1.21) - IF(L37="Découverte", KPI!$C$2, IF(L37="Essentiel", KPI!$C$3, IF(L37="Premium", KPI!$C$4, 0) ) ) - N(X37) - N(AA37) - N(AC37) - IFERROR(INDEX(Stats!$G:$G, MATCH(DATE(YEAR(R37), MONTH(R37), 1), Stats!$A:$A, 0)), 35) )} -> 231.42314 | AH37: reklrh78v49ma6isa41j25eg44@google.com | AI37: OK 2025-12-01 18:55 | AM37: 2025_0052
A38: Fracassi Celine | B38: Celinefracassi@icloud.com | C38: 0495 46 63 54 | D38: FR | F38: 45906 | I38: Rte de Mons 54, 6560 Erquelinnes | J38: Mariage | L38: Premium | M38: 500 | N38: 120 | T38: =SUM(M38:N38) -> 620 | U38: =T38-S38 -> 620 | V38: Abdel | W38: 6 | X38: 70 | Y38: 89 | Z38: 356 | AA38: 53.4 | AC38: =IF(OR(L38="", AB38=""), 0, IF(L38="Découverte", KPI!$F$2, IF(L38="Essentiel", KPI!$F$3, IF(L38="Premium", KPI!$F$4, 0) ) ) ) -> 0 | AD38: {=IF(F38="", "", (T38 / 1.21) - IF(L38="Découverte", KPI!$C$2, IF(L38="Essentiel", KPI!$C$3, IF(L38="Premium", KPI!$C$4, 0) ) ) - N(X38) - N(AA38) - N(AC38) - IFERROR(INDEX(Stats!$G:$G, MATCH(DATE(YEAR(R38), MONTH(R38), 1), Stats!$A:$A, 0)), 35) )} -> 261.49669 | AH38: u5aa3qd1glcpv29ir1roqf6650@google.com | AI38: OK 2025-12-01 18:54 | AM38: 2025_0053
A39: Emma Mabille | B39: Emmamabille8@gmail.com | C39: 0033644373939 | D39: FR | F39: 45906 | I39: 274 allée des marronniers, 59114 Eecke | J39: Mariage | L39: Premium | M39: 500 | N39: 120 | T39: =SUM(M39:N39) -> 620 | U39: =T39-S39 -> 620 | V39: Abdel | W39: 8.5 | X39: 70 | Y39: 156 | Z39: 624 | AA39: 93.6 | AC39: =IF(OR(L39="", AB39=""), 0, IF(L39="Découverte", KPI!$F$2, IF(L39="Essentiel", KPI!$F$3, IF(L39="Premium", KPI!$F$4, 0) ) ) ) -> 0 | AD39: {=IF(F39="", "", (T39 / 1.21) - IF(L39="Découverte", KPI!$C$2, IF(L39="Essentiel", KPI!$C$3, IF(L39="Premium", KPI!$C$4, 0) ) ) - N(X39) - N(AA39) - N(AC39) - IFERROR(INDEX(Stats!$G:$G, MATCH(DATE(YEAR(R39), MONTH(R39), 1), Stats!$A:$A, 0)), 35) )} -> 221.29669 | AH39: 9s7qloq0eke2ovcjqu00jfqjkg@google.com | AI39: OK 2025-12-01 19:11 | AL39: 2025_0014 | AM39: 2025_0055
A40: Eléni & Charel Schroeder | B40: epolissiou@gmail.com | C40: 0493861149 | D40: FR | F40: 45913 | I40: Rue du Village 50 , 5380 Franc-Warêt | J40: Mariage | L40: Essentiel | M40: 450 | N40: 100 | T40: =SUM(M40:N40) -> 550 | U40: =T40-S40 -> 550 | V40: Abdel | W40: 5.5 | X40: 70 | Y40: 78 | Z40: 312 | AA40: 46.8 | AC40: =IF(OR(L40="", AB40=""), 0, IF(L40="Découverte", KPI!$F$2, IF(L40="Essentiel", KPI!$F$3, IF(L40="Premium", KPI!$F$4, 0) ) ) ) -> 0 | AD40: {=IF(F40="", "", (T40 / 1.21) - IF(L40="Découverte", KPI!$C$2, IF(L40="Essentiel", KPI!$C$3, IF(L40="Premium", KPI!$C$4, 0) ) ) - N(X40) - N(AA40) - N(AC40) - IFERROR(INDEX(Stats!$G:$G, MATCH(DATE(YEAR(R40), MONTH(R40), 1), Stats!$A:$A, 0)), 35) )} -> 256.49545 | AH40: f9b76qpo5f67sue5d5n8embq1k@google.com | AI40: OK 2025-12-01 18:54 | AM40: 2025_0056
...

Sheet Stats
A1: Date | B1: # Leads META | C1: Spent META | D1: CPL META | E1: # closing META | F1: Conversion (%) META | G1: CPA META | H1: # Leads Total | I1: CPL Total | J1: # closing Total | K1: Conversion (%) total | L1: CPA G | M1: # C.Découverte | N1: # C.Essentiel | O1: # C.Premium | P1: Acomptes (payés) | Q1: # Events | R1: # E.Découverte | S1: # E.Essentiel | T1: # E.Premium | U1: Total (event) | V1: Acomptes (event) | W1: Restants (event) | X1: CA (Acomptes + Restants) | Y1: CA généré (Event + Transport) | Z1: € transport (Ev. Réalisés) | AA1: Coût packs (Ev. Réalisés) | AB1: Heures étudiants | AC1: Coût staff étudiants | AD1: Essence | AE1: Comm Commerciaux | AF1: Charges fixes mensuelles | AG1: Marge brute opé. (Events) | AH1: Marge nette opé. (Events) | AI1: Cashflow Brut (mensuel) | AJ1: Cashflow Net (mensuel)
A2: 45658 | C2: 750 | D2: =IF(B2=0, 0, C2/B2) -> 0 | E2: =COUNTIFS( Clients!$R:$R, ">="&A2, Clients!$R:$R, "<"&DATE(YEAR(A2), MONTH(A2)+1, 1) ) -> 0 | F2: =IF(B2=0, 0, E2/B2) -> 0 | G2: 35 | I2: =IF(H2=0, 0, #REF!/H2) -> 0 | M2: =COUNTIFS( Clients!$R:$R, ">="&A2, Clients!$R:$R, "<"&DATE(YEAR(A2), MONTH(A2)+1, 1), Clients!$L:$L, "Découverte" ) -> 0 | N2: =COUNTIFS( Clients!$R:$R, ">="&A2, Clients!$R:$R, "<"&DATE(YEAR(A2), MONTH(A2)+1, 1), Clients!$L:$L, "Essentiel" ) -> 0 | O2: =COUNTIFS( Clients!$R:$R, ">="&A2, Clients!$R:$R, "<"&DATE(YEAR(A2), MONTH(A2)+1, 1), Clients!$L:$L, "Premium" ) -> 0 | P2: =SUMIFS( Clients!$S:$S, Clients!$R:$R, ">="&A2, Clients!$R:$R, "<"&DATE(YEAR(A2), MONTH(A2)+1, 1) ) -> 0 | Q2: =COUNTIFS( Clients!$F:$F, ">="&A2, Clients!$F:$F, "<"&DATE(YEAR(A2), MONTH(A2)+1, 1) ) -> 4 | R2: =COUNTIFS( Clients!$F:$F, ">="&A2, Clients!$F:$F, "<"&DATE(YEAR(A2), MONTH(A2)+1, 1), Clients!$L:$L, "Découverte" ) -> 1 | S2: =COUNTIFS( Clients!$F:$F, ">="&A2, Clients!$F:$F, "<"&DATE(YEAR(A2), MONTH(A2)+1, 1), Clients!$L:$L, "Essentiel" ) -> 1 | T2: =COUNTIFS( Clients!$F:$F, ">="&A2, Clients!$F:$F, "<"&DATE(YEAR(A2), MONTH(A2)+1, 1), Clients!$L:$L, "Premium" ) -> 2 | U2: =SUMIFS( Clients!$T:$T, Clients!$F:$F, ">="&A2, Clients!$F:$F, "<"&DATE(YEAR(A2), MONTH(A2)+1, 1) ) -> 2320 | V2: =SUMIFS( Clients!$S:$S, Clients!$F:$F, ">="&A2, Clients!$F:$F, "<"&DATE(YEAR(A2), MONTH(A2)+1, 1) ) -> 0 | W2: =SUMIFS( Clients!$U:$U, Clients!$F:$F, ">="&A2, Clients!$F:$F, "<"&DATE(YEAR(A2), MONTH(A2)+1, 1) ) -> 2320 | X2: =P2 + W2 -> 2320 | Z2: =SUMIFS( Clients!$N:$N, Clients!$F:$F,">="&$A2, Clients!$F:$F,"<"&DATE(YEAR($A2),MONTH($A2)+1,1) ) -> 80 | AA2: =R2 * KPI!$C$2 + S2 * KPI!$C$3 + T2 * KPI!$C$4 -> 254.37 | AB2: =SUMIFS( Clients!$W:$W, Clients!$F:$F,">="&A2, Clients!$F:$F,"<"&DATE(YEAR(A2),MONTH(A2)+1,1) ) -> 19 | AC2: =SUMIFS( Clients!$X:$X, Clients!$F:$F,">="&A2, Clients!$F:$F,"<"&DATE(YEAR(A2),MONTH(A2)+1,1) ) -> 280 | AD2: =SUMIFS( Clients!$AA:$AA, Clients!$F:$F,">="&$A2, Clients!$F:$F,"<"&DATE(YEAR($A2),MONTH($A2)+1,1) ) -> 168.6 | AE2: =SUMIFS( Clients!$AC:$AC, Clients!$R:$R,">="&$A2, Clients!$R:$R,"<"&DATE(YEAR($A2),MONTH($A2)+1,1) ) -> 0 | AF2: =KPI!$B$29 -> 441.64 | AH2: =U2 - AA2 - Z2 - AC2 - AD2 -> 1537.03 | AI2: =(P2 + W2 + Z2) - AA2 - AC2 - AD2 - AE2 -> 1697.03 | AJ2: =AI2 - C2 - AF2 -> 505.39
A3: 45689 | C3: 750 | D3: =IF(B3=0, 0, C3/B3) -> 0 | E3: =COUNTIFS( Clients!$R:$R, ">="&A3, Clients!$R:$R, "<"&DATE(YEAR(A3), MONTH(A3)+1, 1) ) -> 0 | F3: =IF(B3=0, 0, E3/B3) -> 0 | G3: 35 | I3: =IF(H3=0, 0, #REF!/H3) -> 0 | M3: =COUNTIFS( Clients!$R:$R, ">="&A3, Clients!$R:$R, "<"&DATE(YEAR(A3), MONTH(A3)+1, 1), Clients!$L:$L, "Découverte" ) -> 0 | N3: =COUNTIFS( Clients!$R:$R, ">="&A3, Clients!$R:$R, "<"&DATE(YEAR(A3), MONTH(A3)+1, 1), Clients!$L:$L, "Essentiel" ) -> 0 | O3: =COUNTIFS( Clients!$R:$R, ">="&A3, Clients!$R:$R, "<"&DATE(YEAR(A3), MONTH(A3)+1, 1), Clients!$L:$L, "Premium" ) -> 0 | P3: =SUMIFS( Clients!$S:$S, Clients!$R:$R, ">="&A3, Clients!$R:$R, "<"&DATE(YEAR(A3), MONTH(A3)+1, 1) ) -> 0 | Q3: =COUNTIFS( Clients!$F:$F, ">="&A3, Clients!$F:$F, "<"&DATE(YEAR(A3), MONTH(A3)+1, 1) ) -> 0 | R3: =COUNTIFS( Clients!$F:$F, ">="&A3, Clients!$F:$F, "<"&DATE(YEAR(A3), MONTH(A3)+1, 1), Clients!$L:$L, "Découverte" ) -> 0 | S3: =COUNTIFS( Clients!$F:$F, ">="&A3, Clients!$F:$F, "<"&DATE(YEAR(A3), MONTH(A3)+1, 1), Clients!$L:$L, "Essentiel" ) -> 0 | T3: =COUNTIFS( Clients!$F:$F, ">="&A3, Clients!$F:$F, "<"&DATE(YEAR(A3), MONTH(A3)+1, 1), Clients!$L:$L, "Premium" ) -> 0 | U3: =SUMIFS( Clients!$T:$T, Clients!$F:$F, ">="&A3, Clients!$F:$F, "<"&DATE(YEAR(A3), MONTH(A3)+1, 1) ) -> 0 | V3: =SUMIFS( Clients!$S:$S, Clients!$F:$F, ">="&A3, Clients!$F:$F, "<"&DATE(YEAR(A3), MONTH(A3)+1, 1) ) -> 0 | W3: =SUMIFS( Clients!$U:$U, Clients!$F:$F, ">="&A3, Clients!$F:$F, "<"&DATE(YEAR(A3), MONTH(A3)+1, 1) ) -> 0 | X3: =P3 + W3 -> 0 | Z3: =SUMIFS( Clients!$N:$N, Clients!$F:$F,">="&$A3, Clients!$F:$F,"<"&DATE(YEAR($A3),MONTH($A3)+1,1) ) -> 0 | AA3: =R3 * KPI!$C$2 + S3 * KPI!$C$3 + T3 * KPI!$C$4 -> 0 | AB3: =SUMIFS( Clients!$W:$W, Clients!$F:$F,">="&A3, Clients!$F:$F,"<"&DATE(YEAR(A3),MONTH(A3)+1,1) ) -> 0 | AC3: =SUMIFS( Clients!$X:$X, Clients!$F:$F,">="&A3, Clients!$F:$F,"<"&DATE(YEAR(A3),MONTH(A3)+1,1) ) -> 0 | AD3: =SUMIFS( Clients!$AA:$AA, Clients!$F:$F,">="&$A3, Clients!$F:$F,"<"&DATE(YEAR($A3),MONTH($A3)+1,1) ) -> 0 | AE3: =SUMIFS( Clients!$AC:$AC, Clients!$R:$R,">="&$A3, Clients!$R:$R,"<"&DATE(YEAR($A3),MONTH($A3)+1,1) ) -> 0 | AF3: =KPI!$B$29 -> 441.64 | AH3: =U3 - AA3 - Z3 - AC3 - AD3 -> 0 | AI3: =(P3 + W3 + Z3) - AA3 - AC3 - AD3 - AE3 -> 0 | AJ3: =AI3 - C3 - AF3 -> -1191.64
A4: 45717 | C4: 750 | D4: =IF(B4=0, 0, C4/B4) -> 0 | E4: =COUNTIFS( Clients!$R:$R, ">="&A4, Clients!$R:$R, "<"&DATE(YEAR(A4), MONTH(A4)+1, 1) ) -> 0 | F4: =IF(B4=0, 0, E4/B4) -> 0 | G4: 35 | I4: =IF(H4=0, 0, #REF!/H4) -> 0 | M4: =COUNTIFS( Clients!$R:$R, ">="&A4, Clients!$R:$R, "<"&DATE(YEAR(A4), MONTH(A4)+1, 1), Clients!$L:$L, "Découverte" ) -> 0 | N4: =COUNTIFS( Clients!$R:$R, ">="&A4, Clients!$R:$R, "<"&DATE(YEAR(A4), MONTH(A4)+1, 1), Clients!$L:$L, "Essentiel" ) -> 0 | O4: =COUNTIFS( Clients!$R:$R, ">="&A4, Clients!$R:$R, "<"&DATE(YEAR(A4), MONTH(A4)+1, 1), Clients!$L:$L, "Premium" ) -> 0 | P4: =SUMIFS( Clients!$S:$S, Clients!$R:$R, ">="&A4, Clients!$R:$R, "<"&DATE(YEAR(A4), MONTH(A4)+1, 1) ) -> 0 | Q4: =COUNTIFS( Clients!$F:$F, ">="&A4, Clients!$F:$F, "<"&DATE(YEAR(A4), MONTH(A4)+1, 1) ) -> 1 | R4: =COUNTIFS( Clients!$F:$F, ">="&A4, Clients!$F:$F, "<"&DATE(YEAR(A4), MONTH(A4)+1, 1), Clients!$L:$L, "Découverte" ) -> 0 | S4: =COUNTIFS( Clients!$F:$F, ">="&A4, Clients!$F:$F, "<"&DATE(YEAR(A4), MONTH(A4)+1, 1), Clients!$L:$L, "Essentiel" ) -> 0 | T4: =COUNTIFS( Clients!$F:$F, ">="&A4, Clients!$F:$F, "<"&DATE(YEAR(A4), MONTH(A4)+1, 1), Clients!$L:$L, "Premium" ) -> 1 | U4: =SUMIFS( Clients!$T:$T, Clients!$F:$F, ">="&A4, Clients!$F:$F, "<"&DATE(YEAR(A4), MONTH(A4)+1, 1) ) -> 580 | V4: =SUMIFS( Clients!$S:$S, Clients!$F:$F, ">="&A4, Clients!$F:$F, "<"&DATE(YEAR(A4), MONTH(A4)+1, 1) ) -> 0 | W4: =SUMIFS( Clients!$U:$U, Clients!$F:$F, ">="&A4, Clients!$F:$F, "<"&DATE(YEAR(A4), MONTH(A4)+1, 1) ) -> 580 | X4: =P4 + W4 -> 580 | Z4: =SUMIFS( Clients!$N:$N, Clients!$F:$F,">="&$A4, Clients!$F:$F,"<"&DATE(YEAR($A4),MONTH($A4)+1,1) ) -> 80 | AA4: =R4 * KPI!$C$2 + S4 * KPI!$C$3 + T4 * KPI!$C$4 -> 92.5 | AB4: =SUMIFS( Clients!$W:$W, Clients!$F:$F,">="&A4, Clients!$F:$F,"<"&DATE(YEAR(A4),MONTH(A4)+1,1) ) -> 5 | AC4: =SUMIFS( Clients!$X:$X, Clients!$F:$F,">="&A4, Clients!$F:$F,"<"&DATE(YEAR(A4),MONTH(A4)+1,1) ) -> 70 | AD4: =SUMIFS( Clients!$AA:$AA, Clients!$F:$F,">="&$A4, Clients!$F:$F,"<"&DATE(YEAR($A4),MONTH($A4)+1,1) ) -> 47.4 | AE4: =SUMIFS( Clients!$AC:$AC, Clients!$R:$R,">="&$A4, Clients!$R:$R,"<"&DATE(YEAR($A4),MONTH($A4)+1,1) ) -> 0 | AF4: =KPI!$B$29 -> 441.64 | AH4: =U4 - AA4 - Z4 - AC4 - AD4 -> 290.1 | AI4: =(P4 + W4 + Z4) - AA4 - AC4 - AD4 - AE4 -> 450.1 | AJ4: =AI4 - C4 - AF4 -> -741.54
A5: 45748 | C5: 750 | D5: =IF(B5=0, 0, C5/B5) -> 0 | E5: =COUNTIFS( Clients!$R:$R, ">="&A5, Clients!$R:$R, "<"&DATE(YEAR(A5), MONTH(A5)+1, 1) ) -> 0 | F5: =IF(B5=0, 0, E5/B5) -> 0 | G5: 35 | I5: =IF(H5=0, 0, #REF!/H5) -> 0 | M5: =COUNTIFS( Clients!$R:$R, ">="&A5, Clients!$R:$R, "<"&DATE(YEAR(A5), MONTH(A5)+1, 1), Clients!$L:$L, "Découverte" ) -> 0 | N5: =COUNTIFS( Clients!$R:$R, ">="&A5, Clients!$R:$R, "<"&DATE(YEAR(A5), MONTH(A5)+1, 1), Clients!$L:$L, "Essentiel" ) -> 0 | O5: =COUNTIFS( Clients!$R:$R, ">="&A5, Clients!$R:$R, "<"&DATE(YEAR(A5), MONTH(A5)+1, 1), Clients!$L:$L, "Premium" ) -> 0 | P5: =SUMIFS( Clients!$S:$S, Clients!$R:$R, ">="&A5, Clients!$R:$R, "<"&DATE(YEAR(A5), MONTH(A5)+1, 1) ) -> 0 | Q5: =COUNTIFS( Clients!$F:$F, ">="&A5, Clients!$F:$F, "<"&DATE(YEAR(A5), MONTH(A5)+1, 1) ) -> 3 | R5: =COUNTIFS( Clients!$F:$F, ">="&A5, Clients!$F:$F, "<"&DATE(YEAR(A5), MONTH(A5)+1, 1), Clients!$L:$L, "Découverte" ) -> 0 | S5: =COUNTIFS( Clients!$F:$F, ">="&A5, Clients!$F:$F, "<"&DATE(YEAR(A5), MONTH(A5)+1, 1), Clients!$L:$L, "Essentiel" ) -> 0 | T5: =COUNTIFS( Clients!$F:$F, ">="&A5, Clients!$F:$F, "<"&DATE(YEAR(A5), MONTH(A5)+1, 1), Clients!$L:$L, "Premium" ) -> 3 | U5: =SUMIFS( Clients!$T:$T, Clients!$F:$F, ">="&A5, Clients!$F:$F, "<"&DATE(YEAR(A5), MONTH(A5)+1, 1) ) -> 1490 | V5: =SUMIFS( Clients!$S:$S, Clients!$F:$F, ">="&A5, Clients!$F:$F, "<"&DATE(YEAR(A5), MONTH(A5)+1, 1) ) -> 0 | W5: =SUMIFS( Clients!$U:$U, Clients!$F:$F, ">="&A5, Clients!$F:$F, "<"&DATE(YEAR(A5), MONTH(A5)+1, 1) ) -> 1490 | X5: =P5 + W5 -> 1490 | Z5: =SUMIFS( Clients!$N:$N, Clients!$F:$F,">="&$A5, Clients!$F:$F,"<"&DATE(YEAR($A5),MONTH($A5)+1,1) ) -> 290 | AA5: =R5 * KPI!$C$2 + S5 * KPI!$C$3 + T5 * KPI!$C$4 -> 277.5 | AB5: =SUMIFS( Clients!$W:$W, Clients!$F:$F,">="&A5, Clients!$F:$F,"<"&DATE(YEAR(A5),MONTH(A5)+1,1) ) -> 17.5 | AC5: =SUMIFS( Clients!$X:$X, Clients!$F:$F,">="&A5, Clients!$F:$F,"<"&DATE(YEAR(A5),MONTH(A5)+1,1) ) -> 210 | AD5: =SUMIFS( Clients!$AA:$AA, Clients!$F:$F,">="&$A5, Clients!$F:$F,"<"&DATE(YEAR($A5),MONTH($A5)+1,1) ) -> 163.2 | AE5: =SUMIFS( Clients!$AC:$AC, Clients!$R:$R,">="&$A5, Clients!$R:$R,"<"&DATE(YEAR($A5),MONTH($A5)+1,1) ) -> 0 | AF5: =KPI!$B$29 -> 441.64 | AH5: =U5 - AA5 - Z5 - AC5 - AD5 -> 549.3 | AI5: =(P5 + W5 + Z5) - AA5 - AC5 - AD5 - AE5 -> 1129.3 | AJ5: =AI5 - C5 - AF5 -> -62.34
A6: 45778 | C6: 750 | D6: =IF(B6=0, 0, C6/B6) -> 0 | E6: =COUNTIFS( Clients!$R:$R, ">="&A6, Clients!$R:$R, "<"&DATE(YEAR(A6), MONTH(A6)+1, 1) ) -> 0 | F6: =IF(B6=0, 0, E6/B6) -> 0 | G6: 35 | I6: =IF(H6=0, 0, #REF!/H6) -> 0 | M6: =COUNTIFS( Clients!$R:$R, ">="&A6, Clients!$R:$R, "<"&DATE(YEAR(A6), MONTH(A6)+1, 1), Clients!$L:$L, "Découverte" ) -> 0 | N6: =COUNTIFS( Clients!$R:$R, ">="&A6, Clients!$R:$R, "<"&DATE(YEAR(A6), MONTH(A6)+1, 1), Clients!$L:$L, "Essentiel" ) -> 0 | O6: =COUNTIFS( Clients!$R:$R, ">="&A6, Clients!$R:$R, "<"&DATE(YEAR(A6), MONTH(A6)+1, 1), Clients!$L:$L, "Premium" ) -> 0 | P6: =SUMIFS( Clients!$S:$S, Clients!$R:$R, ">="&A6, Clients!$R:$R, "<"&DATE(YEAR(A6), MONTH(A6)+1, 1) ) -> 0 | Q6: =COUNTIFS( Clients!$F:$F, ">="&A6, Clients!$F:$F, "<"&DATE(YEAR(A6), MONTH(A6)+1, 1) ) -> 7 | R6: =COUNTIFS( Clients!$F:$F, ">="&A6, Clients!$F:$F, "<"&DATE(YEAR(A6), MONTH(A6)+1, 1), Clients!$L:$L, "Découverte" ) -> 0 | S6: =COUNTIFS( Clients!$F:$F, ">="&A6, Clients!$F:$F, "<"&DATE(YEAR(A6), MONTH(A6)+1, 1), Clients!$L:$L, "Essentiel" ) -> 2 | T6: =COUNTIFS( Clients!$F:$F, ">="&A6, Clients!$F:$F, "<"&DATE(YEAR(A6), MONTH(A6)+1, 1), Clients!$L:$L, "Premium" ) -> 5 | U6: =SUMIFS( Clients!$T:$T, Clients!$F:$F, ">="&A6, Clients!$F:$F, "<"&DATE(YEAR(A6), MONTH(A6)+1, 1) ) -> 3715 | V6: =SUMIFS( Clients!$S:$S, Clients!$F:$F, ">="&A6, Clients!$F:$F, "<"&DATE(YEAR(A6), MONTH(A6)+1, 1) ) -> 0 | W6: =SUMIFS( Clients!$U:$U, Clients!$F:$F, ">="&A6, Clients!$F:$F, "<"&DATE(YEAR(A6), MONTH(A6)+1, 1) ) -> 3715 | X6: =P6 + W6 -> 3715 | Z6: =SUMIFS( Clients!$N:$N, Clients!$F:$F,">="&$A6, Clients!$F:$F,"<"&DATE(YEAR($A6),MONTH($A6)+1,1) ) -> 315 | AA6: =R6 * KPI!$C$2 + S6 * KPI!$C$3 + T6 * KPI!$C$4 -> 555 | AB6: =SUMIFS( Clients!$W:$W, Clients!$F:$F,">="&A6, Clients!$F:$F,"<"&DATE(YEAR(A6),MONTH(A6)+1,1) ) -> 23 | AC6: =SUMIFS( Clients!$X:$X, Clients!$F:$F,">="&A6, Clients!$F:$F,"<"&DATE(YEAR(A6),MONTH(A6)+1,1) ) -> 490 | AD6: =SUMIFS( Clients!$AA:$AA, Clients!$F:$F,">="&$A6, Clients!$F:$F,"<"&DATE(YEAR($A6),MONTH($A6)+1,1) ) -> 131.4 | AE6: =SUMIFS( Clients!$AC:$AC, Clients!$R:$R,">="&$A6, Clients!$R:$R,"<"&DATE(YEAR($A6),MONTH($A6)+1,1) ) -> 0 | AF6: =KPI!$B$29 -> 441.64 | AH6: =U6 - AA6 - Z6 - AC6 - AD6 -> 2223.6 | AI6: =(P6 + W6 + Z6) - AA6 - AC6 - AD6 - AE6 -> 2853.6 | AJ6: =AI6 - C6 - AF6 -> 1661.96
A7: 45809 | C7: 750 | D7: =IF(B7=0, 0, C7/B7) -> 0 | E7: =COUNTIFS( Clients!$R:$R, ">="&A7, Clients!$R:$R, "<"&DATE(YEAR(A7), MONTH(A7)+1, 1) ) -> 0 | F7: =IF(B7=0, 0, E7/B7) -> 0 | G7: 35 | I7: =IF(H7=0, 0, #REF!/H7) -> 0 | M7: =COUNTIFS( Clients!$R:$R, ">="&A7, Clients!$R:$R, "<"&DATE(YEAR(A7), MONTH(A7)+1, 1), Clients!$L:$L, "Découverte" ) -> 0 | N7: =COUNTIFS( Clients!$R:$R, ">="&A7, Clients!$R:$R, "<"&DATE(YEAR(A7), MONTH(A7)+1, 1), Clients!$L:$L, "Essentiel" ) -> 0 | O7: =COUNTIFS( Clients!$R:$R, ">="&A7, Clients!$R:$R, "<"&DATE(YEAR(A7), MONTH(A7)+1, 1), Clients!$L:$L, "Premium" ) -> 0 | P7: =SUMIFS( Clients!$S:$S, Clients!$R:$R, ">="&A7, Clients!$R:$R, "<"&DATE(YEAR(A7), MONTH(A7)+1, 1) ) -> 0 | Q7: =COUNTIFS( Clients!$F:$F, ">="&A7, Clients!$F:$F, "<"&DATE(YEAR(A7), MONTH(A7)+1, 1) ) -> 5 | R7: =COUNTIFS( Clients!$F:$F, ">="&A7, Clients!$F:$F, "<"&DATE(YEAR(A7), MONTH(A7)+1, 1), Clients!$L:$L, "Découverte" ) -> 1 | S7: =COUNTIFS( Clients!$F:$F, ">="&A7, Clients!$F:$F, "<"&DATE(YEAR(A7), MONTH(A7)+1, 1), Clients!$L:$L, "Essentiel" ) -> 1 | T7: =COUNTIFS( Clients!$F:$F, ">="&A7, Clients!$F:$F, "<"&DATE(YEAR(A7), MONTH(A7)+1, 1), Clients!$L:$L, "Premium" ) -> 3 | U7: =SUMIFS( Clients!$T:$T, Clients!$F:$F, ">="&A7, Clients!$F:$F, "<"&DATE(YEAR(A7), MONTH(A7)+1, 1) ) -> 2300 | V7: =SUMIFS( Clients!$S:$S, Clients!$F:$F, ">="&A7, Clients!$F:$F, "<"&DATE(YEAR(A7), MONTH(A7)+1, 1) ) -> 0 | W7: =SUMIFS( Clients!$U:$U, Clients!$F:$F, ">="&A7, Clients!$F:$F, "<"&DATE(YEAR(A7), MONTH(A7)+1, 1) ) -> 2300 | X7: =P7 + W7 -> 2300 | Z7: =SUMIFS( Clients!$N:$N, Clients!$F:$F,">="&$A7, Clients!$F:$F,"<"&DATE(YEAR($A7),MONTH($A7)+1,1) ) -> 100 | AA7: =R7 * KPI!$C$2 + S7 * KPI!$C$3 + T7 * KPI!$C$4 -> 346.87 | AB7: =SUMIFS( Clients!$W:$W, Clients!$F:$F,">="&A7, Clients!$F:$F,"<"&DATE(YEAR(A7),MONTH(A7)+1,1) ) -> 10.5 | AC7: =SUMIFS( Clients!$X:$X, Clients!$F:$F,">="&A7, Clients!$F:$F,"<"&DATE(YEAR(A7),MONTH(A7)+1,1) ) -> 350 | AD7: =SUMIFS( Clients!$AA:$AA, Clients!$F:$F,">="&$A7, Clients!$F:$F,"<"&DATE(YEAR($A7),MONTH($A7)+1,1) ) -> 58.8 | AE7: =SUMIFS( Clients!$AC:$AC, Clients!$R:$R,">="&$A7, Clients!$R:$R,"<"&DATE(YEAR($A7),MONTH($A7)+1,1) ) -> 0 | AF7: =KPI!$B$29 -> 441.64 | AH7: =U7 - AA7 - Z7 - AC7 - AD7 -> 1444.33 | AI7: =(P7 + W7 + Z7) - AA7 - AC7 - AD7 - AE7 -> 1644.33 | AJ7: =AI7 - C7 - AF7 -> 452.69
A8: 45839 | C8: 750 | D8: =IF(B8=0, 0, C8/B8) -> 0 | E8: =COUNTIFS( Clients!$R:$R, ">="&A8, Clients!$R:$R, "<"&DATE(YEAR(A8), MONTH(A8)+1, 1) ) -> 0 | F8: =IF(B8=0, 0, E8/B8) -> 0 | G8: 35 | I8: =IF(H8=0, 0, #REF!/H8) -> 0 | M8: =COUNTIFS( Clients!$R:$R, ">="&A8, Clients!$R:$R, "<"&DATE(YEAR(A8), MONTH(A8)+1, 1), Clients!$L:$L, "Découverte" ) -> 0 | N8: =COUNTIFS( Clients!$R:$R, ">="&A8, Clients!$R:$R, "<"&DATE(YEAR(A8), MONTH(A8)+1, 1), Clients!$L:$L, "Essentiel" ) -> 0 | O8: =COUNTIFS( Clients!$R:$R, ">="&A8, Clients!$R:$R, "<"&DATE(YEAR(A8), MONTH(A8)+1, 1), Clients!$L:$L, "Premium" ) -> 0 | P8: =SUMIFS( Clients!$S:$S, Clients!$R:$R, ">="&A8, Clients!$R:$R, "<"&DATE(YEAR(A8), MONTH(A8)+1, 1) ) -> 0 | Q8: =COUNTIFS( Clients!$F:$F, ">="&A8, Clients!$F:$F, "<"&DATE(YEAR(A8), MONTH(A8)+1, 1) ) -> 3 | R8: =COUNTIFS( Clients!$F:$F, ">="&A8, Clients!$F:$F, "<"&DATE(YEAR(A8), MONTH(A8)+1, 1), Clients!$L:$L, "Découverte" ) -> 0 | S8: =COUNTIFS( Clients!$F:$F, ">="&A8, Clients!$F:$F, "<"&DATE(YEAR(A8), MONTH(A8)+1, 1), Clients!$L:$L, "Essentiel" ) -> 0 | T8: =COUNTIFS( Clients!$F:$F, ">="&A8, Clients!$F:$F, "<"&DATE(YEAR(A8), MONTH(A8)+1, 1), Clients!$L:$L, "Premium" ) -> 3 | U8: =SUMIFS( Clients!$T:$T, Clients!$F:$F, ">="&A8, Clients!$F:$F, "<"&DATE(YEAR(A8), MONTH(A8)+1, 1) ) -> 1845 | V8: =SUMIFS( Clients!$S:$S, Clients!$F:$F, ">="&A8, Clients!$F:$F, "<"&DATE(YEAR(A8), MONTH(A8)+1, 1) ) -> 0 | W8: =SUMIFS( Clients!$U:$U, Clients!$F:$F, ">="&A8, Clients!$F:$F, "<"&DATE(YEAR(A8), MONTH(A8)+1, 1) ) -> 1845 | X8: =P8 + W8 -> 1845 | Z8: =SUMIFS( Clients!$N:$N, Clients!$F:$F,">="&$A8, Clients!$F:$F,"<"&DATE(YEAR($A8),MONTH($A8)+1,1) ) -> 345 | AA8: =R8 * KPI!$C$2 + S8 * KPI!$C$3 + T8 * KPI!$C$4 -> 277.5 | AB8: =SUMIFS( Clients!$W:$W, Clients!$F:$F,">="&A8, Clients!$F:$F,"<"&DATE(YEAR(A8),MONTH(A8)+1,1) ) -> 20.5 | AC8: =SUMIFS( Clients!$X:$X, Clients!$F:$F,">="&A8, Clients!$F:$F,"<"&DATE(YEAR(A8),MONTH(A8)+1,1) ) -> 210 | AD8: =SUMIFS( Clients!$AA:$AA, Clients!$F:$F,">="&$A8, Clients!$F:$F,"<"&DATE(YEAR($A8),MONTH($A8)+1,1) ) -> 198 | AE8: =SUMIFS( Clients!$AC:$AC, Clients!$R:$R,">="&$A8, Clients!$R:$R,"<"&DATE(YEAR($A8),MONTH($A8)+1,1) ) -> 0 | AF8: =KPI!$B$29 -> 441.64 | AH8: =U8 - AA8 - Z8 - AC8 - AD8 -> 814.5 | AI8: =(P8 + W8 + Z8) - AA8 - AC8 - AD8 - AE8 -> 1504.5 | AJ8: =AI8 - C8 - AF8 -> 312.86
A9: 45870 | C9: 750 | D9: =IF(B9=0, 0, C9/B9) -> 0 | E9: =COUNTIFS( Clients!$R:$R, ">="&A9, Clients!$R:$R, "<"&DATE(YEAR(A9), MONTH(A9)+1, 1) ) -> 1 | F9: =IF(B9=0, 0, E9/B9) -> 0 | G9: 35 | I9: =IF(H9=0, 0, #REF!/H9) -> 0 | M9: =COUNTIFS( Clients!$R:$R, ">="&A9, Clients!$R:$R, "<"&DATE(YEAR(A9), MONTH(A9)+1, 1), Clients!$L:$L, "Découverte" ) -> 0 | N9: =COUNTIFS( Clients!$R:$R, ">="&A9, Clients!$R:$R, "<"&DATE(YEAR(A9), MONTH(A9)+1, 1), Clients!$L:$L, "Essentiel" ) -> 0 | O9: =COUNTIFS( Clients!$R:$R, ">="&A9, Clients!$R:$R, "<"&DATE(YEAR(A9), MONTH(A9)+1, 1), Clients!$L:$L, "Premium" ) -> 1 | P9: =SUMIFS( Clients!$S:$S, Clients!$R:$R, ">="&A9, Clients!$R:$R, "<"&DATE(YEAR(A9), MONTH(A9)+1, 1) ) -> 0 | Q9: =COUNTIFS( Clients!$F:$F, ">="&A9, Clients!$F:$F, "<"&DATE(YEAR(A9), MONTH(A9)+1, 1) ) -> 11 | R9: =COUNTIFS( Clients!$F:$F, ">="&A9, Clients!$F:$F, "<"&DATE(YEAR(A9), MONTH(A9)+1, 1), Clients!$L:$L, "Découverte" ) -> 0 | S9: =COUNTIFS( Clients!$F:$F, ">="&A9, Clients!$F:$F, "<"&DATE(YEAR(A9), MONTH(A9)+1, 1), Clients!$L:$L, "Essentiel" ) -> 4 | T9: =COUNTIFS( Clients!$F:$F, ">="&A9, Clients!$F:$F, "<"&DATE(YEAR(A9), MONTH(A9)+1, 1), Clients!$L:$L, "Premium" ) -> 6 | U9: =SUMIFS( Clients!$T:$T, Clients!$F:$F, ">="&A9, Clients!$F:$F, "<"&DATE(YEAR(A9), MONTH(A9)+1, 1) ) -> 6430 | V9: =SUMIFS( Clients!$S:$S, Clients!$F:$F, ">="&A9, Clients!$F:$F, "<"&DATE(YEAR(A9), MONTH(A9)+1, 1) ) -> 0 | W9: =SUMIFS( Clients!$U:$U, Clients!$F:$F, ">="&A9, Clients!$F:$F, "<"&DATE(YEAR(A9), MONTH(A9)+1, 1) ) -> 6430 | X9: =P9 + W9 -> 6430 | Z9: =SUMIFS( Clients!$N:$N, Clients!$F:$F,">="&$A9, Clients!$F:$F,"<"&DATE(YEAR($A9),MONTH($A9)+1,1) ) -> 980 | AA9: =R9 * KPI!$C$2 + S9 * KPI!$C$3 + T9 * KPI!$C$4 -> 740 | AB9: =SUMIFS( Clients!$W:$W, Clients!$F:$F,">="&A9, Clients!$F:$F,"<"&DATE(YEAR(A9),MONTH(A9)+1,1) ) -> 56.5 | AC9: =SUMIFS( Clients!$X:$X, Clients!$F:$F,">="&A9, Clients!$F:$F,"<"&DATE(YEAR(A9),MONTH(A9)+1,1) ) -> 770 | AD9: =SUMIFS( Clients!$AA:$AA, Clients!$F:$F,">="&$A9, Clients!$F:$F,"<"&DATE(YEAR($A9),MONTH($A9)+1,1) ) -> 522 | AE9: =SUMIFS( Clients!$AC:$AC, Clients!$R:$R,">="&$A9, Clients!$R:$R,"<"&DATE(YEAR($A9),MONTH($A9)+1,1) ) -> 0 | AF9: =KPI!$B$29 -> 441.64 | AH9: =U9 - AA9 - Z9 - AC9 - AD9 -> 3418 | AI9: =(P9 + W9 + Z9) - AA9 - AC9 - AD9 - AE9 -> 5378 | AJ9: =AI9 - C9 - AF9 -> 4186.36
A10: 45901 | B10: 217 | C10: =294.23 + 95.34 + 59.01 + 34.72 + 4.94 -> 488.24 | D10: =IF(B10=0, 0, C10/B10) -> 2.2499539 | E10: =COUNTIFS( Clients!$R:$R, ">="&A10, Clients!$R:$R, "<"&DATE(YEAR(A10), MONTH(A10)+1, 1) ) -> 15 | F10: =IF(B10=0, 0, E10/B10) -> 0.069124424 | G10: =IF(E10=0, 0, C10/E10) -> 32.549333 | I10: =IF(H10=0, 0, #REF!/H10) -> 0 | K10: =IF(H10=0, 0, J10/H10) -> 0 | L10: =IF(J10=0, 0, #REF!/J10) -> 0 | M10: =COUNTIFS( Clients!$R:$R, ">="&A10, Clients!$R:$R, "<"&DATE(YEAR(A10), MONTH(A10)+1, 1), Clients!$L:$L, "Découverte" ) -> 4 | N10: =COUNTIFS( Clients!$R:$R, ">="&A10, Clients!$R:$R, "<"&DATE(YEAR(A10), MONTH(A10)+1, 1), Clients!$L:$L, "Essentiel" ) -> 8 | O10: =COUNTIFS( Clients!$R:$R, ">="&A10, Clients!$R:$R, "<"&DATE(YEAR(A10), MONTH(A10)+1, 1), Clients!$L:$L, "Premium" ) -> 3 | P10: =SUMIFS( Clients!$S:$S, Clients!$R:$R, ">="&A10, Clients!$R:$R, "<"&DATE(YEAR(A10), MONTH(A10)+1, 1) ) -> 2250 | Q10: =COUNTIFS( Clients!$F:$F, ">="&A10, Clients!$F:$F, "<"&DATE(YEAR(A10), MONTH(A10)+1, 1) ) -> 10 | R10: =COUNTIFS( Clients!$F:$F, ">="&A10, Clients!$F:$F, "<"&DATE(YEAR(A10), MONTH(A10)+1, 1), Clients!$L:$L, "Découverte" ) -> 1 | S10: =COUNTIFS( Clients!$F:$F, ">="&A10, Clients!$F:$F, "<"&DATE(YEAR(A10), MONTH(A10)+1, 1), Clients!$L:$L, "Essentiel" ) -> 3 | T10: =COUNTIFS( Clients!$F:$F, ">="&A10, Clients!$F:$F, "<"&DATE(YEAR(A10), MONTH(A10)+1, 1), Clients!$L:$L, "Premium" ) -> 6 | U10: =SUMIFS( Clients!$T:$T, Clients!$F:$F, ">="&A10, Clients!$F:$F, "<"&DATE(YEAR(A10), MONTH(A10)+1, 1) ) -> 6510 | V10: =SUMIFS( Clients!$S:$S, Clients!$F:$F, ">="&A10, Clients!$F:$F, "<"&DATE(YEAR(A10), MONTH(A10)+1, 1) ) -> 150 | W10: =SUMIFS( Clients!$U:$U, Clients!$F:$F, ">="&A10, Clients!$F:$F, "<"&DATE(YEAR(A10), MONTH(A10)+1, 1) ) -> 6360 | X10: =P10 + W10 -> 8610 | Y10: =SUMIFS( Clients!T:T, Clients!R:R, ">=" & DATE(YEAR(A10), MONTH(A10), 1), Clients!R:R, "<" & DATE(YEAR(A10), MONTH(A10)+1, 1) ) -> 6450 | Z10: =SUMIFS( Clients!$N:$N, Clients!$F:$F,">="&$A10, Clients!$F:$F,"<"&DATE(YEAR($A10),MONTH($A10)+1,1) ) -> 700.5 | AA10: =R10 * KPI!$C$2 + S10 * KPI!$C$3 + T10 * KPI!$C$4 -> 716.87 | AB10: =SUMIFS( Clients!$W:$W, Clients!$F:$F,">="&A10, Clients!$F:$F,"<"&DATE(YEAR(A10),MONTH(A10)+1,1) ) -> 45.5 | AC10: =SUMIFS( Clients!$X:$X, Clients!$F:$F,">="&A10, Clients!$F:$F,"<"&DATE(YEAR(A10),MONTH(A10)+1,1) ) -> 700 | AD10: =SUMIFS( Clients!$AA:$AA, Clients!$F:$F,">="&$A10, Clients!$F:$F,"<"&DATE(YEAR($A10),MONTH($A10)+1,1) ) -> 343.8 | AE10: =SUMIFS( Clients!$AC:$AC, Clients!$R:$R,">="&$A10, Clients!$R:$R,"<"&DATE(YEAR($A10),MONTH($A10)+1,1) ) -> 0 | AF10: =KPI!$B$29 -> 441.64 | AG10: =U10 - AA10 -> 5793.13 | AH10: =U10 - AA10 - AC10 - AD10 -> 4749.33 | AI10: =(P10 + W10 + Z10) - AA10 - AC10 - AD10 - AE10 -> 7549.83 | AJ10: =AI10 - C10 - AF10 -> 6619.95
A11: 45931 | B11: 278 | C11: =94.42+2.56+16.72+827.63+32.1 -> 973.43 | D11: =IF(B11=0, 0, C11/B11) -> 3.5015468 | E11: =COUNTIFS( Clients!$R:$R, ">="&A11, Clients!$R:$R, "<"&DATE(YEAR(A11), MONTH(A11)+1, 1) ) -> 23 | F11: =IF(B11=0, 0, E11/B11) -> 0.082733813 | G11: =IF(E11=0, 0, C11/E11) -> 42.323043 | I11: =IF(H11=0, 0, #REF!/H11) -> 0 | K11: =IF(H11=0, 0, J11/H11) -> 0 | L11: =IF(J11=0, 0, #REF!/J11) -> 0 | M11: =COUNTIFS( Clients!$R:$R, ">="&A11, Clients!$R:$R, "<"&DATE(YEAR(A11), MONTH(A11)+1, 1), Clients!$L:$L, "Découverte" ) -> 10 | N11: =COUNTIFS( Clients!$R:$R, ">="&A11, Clients!$R:$R, "<"&DATE(YEAR(A11), MONTH(A11)+1, 1), Clients!$L:$L, "Essentiel" ) -> 9 | O11: =COUNTIFS( Clients!$R:$R, ">="&A11, Clients!$R:$R, "<"&DATE(YEAR(A11), MONTH(A11)+1, 1), Clients!$L:$L, "Premium" ) -> 4 | P11: =SUMIFS( Clients!$S:$S, Clients!$R:$R, ">="&A11, Clients!$R:$R, "<"&DATE(YEAR(A11), MONTH(A11)+1, 1) ) -> 3450 | Q11: =COUNTIFS( Clients!$F:$F, ">="&A11, Clients!$F:$F, "<"&DATE(YEAR(A11), MONTH(A11)+1, 1) ) -> 9 | R11: =COUNTIFS( Clients!$F:$F, ">="&A11, Clients!$F:$F, "<"&DATE(YEAR(A11), MONTH(A11)+1, 1), Clients!$L:$L, "Découverte" ) -> 4 | S11: =COUNTIFS( Clients!$F:$F, ">="&A11, Clients!$F:$F, "<"&DATE(YEAR(A11), MONTH(A11)+1, 1), Clients!$L:$L, "Essentiel" ) -> 2 | T11: =COUNTIFS( Clients!$F:$F, ">="&A11, Clients!$F:$F, "<"&DATE(YEAR(A11), MONTH(A11)+1, 1), Clients!$L:$L, "Premium" ) -> 3 | U11: =SUMIFS( Clients!$T:$T, Clients!$F:$F, ">="&A11, Clients!$F:$F, "<"&DATE(YEAR(A11), MONTH(A11)+1, 1) ) -> 3995 | V11: =SUMIFS( Clients!$S:$S, Clients!$F:$F, ">="&A11, Clients!$F:$F, "<"&DATE(YEAR(A11), MONTH(A11)+1, 1) ) -> 900 | W11: =SUMIFS( Clients!$U:$U, Clients!$F:$F, ">="&A11, Clients!$F:$F, "<"&DATE(YEAR(A11), MONTH(A11)+1, 1) ) -> 3095 | X11: =P11 + W11 -> 6545 | Y11: =SUMIFS( Clients!T:T, Clients!R:R, ">=" & DATE(YEAR(A11), MONTH(A11), 1), Clients!R:R, "<" & DATE(YEAR(A11), MONTH(A11)+1, 1) ) -> 10160 | Z11: =SUMIFS( Clients!$N:$N, Clients!$F:$F,">="&$A11, Clients!$F:$F,"<"&DATE(YEAR($A11),MONTH($A11)+1,1) ) -> 595 | AA11: =R11 * KPI!$C$2 + S11 * KPI!$C$3 + T11 * KPI!$C$4 -> 462.48 | AB11: =SUMIFS( Clients!$W:$W, Clients!$F:$F,">="&A11, Clients!$F:$F,"<"&DATE(YEAR(A11),MONTH(A11)+1,1) ) -> 36.5 | AC11: =AB11*14 -> 511 | AD11: =SUMIFS( Clients!$AA:$AA, Clients!$F:$F,">="&$A11, Clients!$F:$F,"<"&DATE(YEAR($A11),MONTH($A11)+1,1) ) -> 266.4 | AE11: =SUMIFS( Clients!$AC:$AC, Clients!$R:$R,">="&$A11, Clients!$R:$R,"<"&DATE(YEAR($A11),MONTH($A11)+1,1) ) -> 170 | AF11: =KPI!$B$29 -> 441.64 | AG11: =U11 - AA11 -> 3532.52 | AH11: =U11 - AA11 - AC11 - AD11 -> 2755.12 | AI11: =(P11 + W11 + Z11) - AA11 - AC11 - AD11 - AE11 -> 5730.12 | AJ11: =AI11 - C11 - AF11 -> 4315.05
A12: 45962 | B12: 194 | C12: 1019.49 | D12: =IF(B12=0, 0, C12/B12) -> 5.2551031 | E12: =COUNTIFS( Clients!$R:$R, ">="&A12, Clients!$R:$R, "<"&DATE(YEAR(A12), MONTH(A12)+1, 1) ) -> 19 | F12: =IF(B12=0, 0, E12/B12) -> 0.097938144 | G12: =IF(E12=0, 0, C12/E12) -> 53.657368 | I12: =IF(H12=0, 0, #REF!/H12) -> 0 | K12: =IF(H12=0, 0, J12/H12) -> 0 | L12: =IF(J12=0, 0, #REF!/J12) -> 0 | M12: =COUNTIFS( Clients!$R:$R, ">="&A12, Clients!$R:$R, "<"&DATE(YEAR(A12), MONTH(A12)+1, 1), Clients!$L:$L, "Découverte" ) -> 2 | N12: =COUNTIFS( Clients!$R:$R, ">="&A12, Clients!$R:$R, "<"&DATE(YEAR(A12), MONTH(A12)+1, 1), Clients!$L:$L, "Essentiel" ) -> 15 | O12: =COUNTIFS( Clients!$R:$R, ">="&A12, Clients!$R:$R, "<"&DATE(YEAR(A12), MONTH(A12)+1, 1), Clients!$L:$L, "Premium" ) -> 2 | P12: =SUMIFS( Clients!$S:$S, Clients!$R:$R, ">="&A12, Clients!$R:$R, "<"&DATE(YEAR(A12), MONTH(A12)+1, 1) ) -> 2850 | Q12: =COUNTIFS( Clients!$F:$F, ">="&A12, Clients!$F:$F, "<"&DATE(YEAR(A12), MONTH(A12)+1, 1) ) -> 6 | R12: =COUNTIFS( Clients!$F:$F, ">="&A12, Clients!$F:$F, "<"&DATE(YEAR(A12), MONTH(A12)+1, 1), Clients!$L:$L, "Découverte" ) -> 4 | S12: =COUNTIFS( Clients!$F:$F, ">="&A12, Clients!$F:$F, "<"&DATE(YEAR(A12), MONTH(A12)+1, 1), Clients!$L:$L, "Essentiel" ) -> 2 | T12: =COUNTIFS( Clients!$F:$F, ">="&A12, Clients!$F:$F, "<"&DATE(YEAR(A12), MONTH(A12)+1, 1), Clients!$L:$L, "Premium" ) -> 0 | U12: =SUMIFS( Clients!$T:$T, Clients!$F:$F, ">="&A12, Clients!$F:$F, "<"&DATE(YEAR(A12), MONTH(A12)+1, 1) ) -> 2223 | V12: =SUMIFS( Clients!$S:$S, Clients!$F:$F, ">="&A12, Clients!$F:$F, "<"&DATE(YEAR(A12), MONTH(A12)+1, 1) ) -> 750 | W12: =SUMIFS( Clients!$U:$U, Clients!$F:$F, ">="&A12, Clients!$F:$F, "<"&DATE(YEAR(A12), MONTH(A12)+1, 1) ) -> 1473 | X12: =P12 + W12 -> 4323 | Y12: =SUMIFS( Clients!T:T, Clients!R:R, ">=" & DATE(YEAR(A12), MONTH(A12), 1), Clients!R:R, "<" & DATE(YEAR(A12), MONTH(A12)+1, 1) ) -> 9050 | Z12: =SUMIFS( Clients!$N:$N, Clients!$F:$F,">="&$A12, Clients!$F:$F,"<"&DATE(YEAR($A12),MONTH($A12)+1,1) ) -> 370 | AA12: =R12 * KPI!$C$2 + S12 * KPI!$C$3 + T12 * KPI!$C$4 -> 184.98 | AB12: =SUMIFS( Clients!$W:$W, Clients!$F:$F,">="&A12, Clients!$F:$F,"<"&DATE(YEAR(A12),MONTH(A12)+1,1) ) -> 21 | AC12: =AB12*14 -> 294 | AD12: =SUMIFS( Clients!$AA:$AA, Clients!$F:$F,">="&$A12, Clients!$F:$F,"<"&DATE(YEAR($A12),MONTH($A12)+1,1) ) -> 128.4 | AE12: =SUMIFS( Clients!$AC:$AC, Clients!$R:$R,">="&$A12, Clients!$R:$R,"<"&DATE(YEAR($A12),MONTH($A12)+1,1) ) -> 270 | AF12: =KPI!$B$29 -> 441.64 | AG12: =U12 - AA12 -> 2038.02 | AH12: =U12 - AA12 - AC12 - AD12 -> 1615.62 | AI12: =(P12 + W12 + Z12) - AA12 - AC12 - AD12 - AE12 -> 3815.62 | AJ12: =AI12 - C12 - AF12 -> 2354.49
